Exception on /gm/gmtools/profile/11951050037377 [GET]
Traceback (most recent call last):
  File "/usr/local/lib/python2.7/site-packages/flask/app.py", line 1982, in wsgi_app
    response = self.full_dispatch_request()
  File "/usr/local/lib/python2.7/site-packages/flask/app.py", line 1614, in full_dispatch_request
    rv = self.handle_user_exception(e)
  File "/usr/local/lib/python2.7/site-packages/flask/app.py", line 1517, in handle_user_exception
    reraise(exc_type, exc_value, tb)
  File "/usr/local/lib/python2.7/site-packages/flask/app.py", line 1612, in full_dispatch_request
    rv = self.dispatch_request()
  File "/usr/local/lib/python2.7/site-packages/flask/app.py", line 1598, in dispatch_request
    return self.view_functions[rule.endpoint](**req.view_args)
  File "/usr/local/lib/python2.7/site-packages/flask_login/utils.py", line 228, in decorated_view
    return func(*args, **kwargs)
  File "/Users/zouyang/PycharmProjects/GMTools_Flask/route.py", line 408, in gm_tools_controls_profile
    profile['mysql_info'] = query_player_from_mysql(uuid)
  File "/Users/zouyang/PycharmProjects/GMTools_Flask/route.py", line 951, in query_player_from_mysql
    mysql_info['userDesc'] = p.userDesc
AttributeError: 'BaseQuery' object has no attribute 'userDesc'
Exception on /gm/gmtools/profile/11951050037377 [GET]
Traceback (most recent call last):
  File "/usr/local/lib/python2.7/site-packages/flask/app.py", line 1982, in wsgi_app
    response = self.full_dispatch_request()
  File "/usr/local/lib/python2.7/site-packages/flask/app.py", line 1614, in full_dispatch_request
    rv = self.handle_user_exception(e)
  File "/usr/local/lib/python2.7/site-packages/flask/app.py", line 1517, in handle_user_exception
    reraise(exc_type, exc_value, tb)
  File "/usr/local/lib/python2.7/site-packages/flask/app.py", line 1612, in full_dispatch_request
    rv = self.dispatch_request()
  File "/usr/local/lib/python2.7/site-packages/flask/app.py", line 1598, in dispatch_request
    return self.view_functions[rule.endpoint](**req.view_args)
  File "/usr/local/lib/python2.7/site-packages/flask_login/utils.py", line 228, in decorated_view
    return func(*args, **kwargs)
  File "/Users/zouyang/PycharmProjects/GMTools_Flask/route.py", line 409, in gm_tools_controls_profile
    profile['image_url'] = check_image(uuid)
  File "/Users/zouyang/PycharmProjects/GMTools_Flask/imageServerQuery.py", line 7, in check_image
    url = '%s/%s/%s%s' % (urllib.quote(IMAGE_SERVER_URL.encode('utf8'), '~/'), u'check', str(uuid).encode('utf8'))
TypeError: not enough arguments for format string
Exception on /gm/gmtools/profile/11951050037377 [GET]
Traceback (most recent call last):
  File "/usr/local/lib/python2.7/site-packages/flask/app.py", line 1982, in wsgi_app
    response = self.full_dispatch_request()
  File "/usr/local/lib/python2.7/site-packages/flask/app.py", line 1614, in full_dispatch_request
    rv = self.handle_user_exception(e)
  File "/usr/local/lib/python2.7/site-packages/flask/app.py", line 1517, in handle_user_exception
    reraise(exc_type, exc_value, tb)
  File "/usr/local/lib/python2.7/site-packages/flask/app.py", line 1612, in full_dispatch_request
    rv = self.dispatch_request()
  File "/usr/local/lib/python2.7/site-packages/flask/app.py", line 1598, in dispatch_request
    return self.view_functions[rule.endpoint](**req.view_args)
  File "/usr/local/lib/python2.7/site-packages/flask_login/utils.py", line 228, in decorated_view
    return func(*args, **kwargs)
  File "/Users/zouyang/PycharmProjects/GMTools_Flask/route.py", line 409, in gm_tools_controls_profile
    profile['image_url'] = check_image(uuid)
  File "/Users/zouyang/PycharmProjects/GMTools_Flask/imageServerQuery.py", line 8, in check_image
    r = requests.get(url)
  File "/usr/local/lib/python2.7/site-packages/requests/api.py", line 72, in get
    return request('get', url, params=params, **kwargs)
  File "/usr/local/lib/python2.7/site-packages/requests/api.py", line 58, in request
    return session.request(method=method, url=url, **kwargs)
  File "/usr/local/lib/python2.7/site-packages/requests/sessions.py", line 494, in request
    prep = self.prepare_request(req)
  File "/usr/local/lib/python2.7/site-packages/requests/sessions.py", line 437, in prepare_request
    hooks=merge_hooks(request.hooks, self.hooks),
  File "/usr/local/lib/python2.7/site-packages/requests/models.py", line 305, in prepare
    self.prepare_url(url, params)
  File "/usr/local/lib/python2.7/site-packages/requests/models.py", line 379, in prepare_url
    raise MissingSchema(error)
MissingSchema: Invalid URL 'http%3A//115.159.90.11/i/check/11951050037377': No schema supplied. Perhaps you meant http://http%3A//115.159.90.11/i/check/11951050037377?
Exception on /gm/gmtools/profile/11951050037377 [GET]
Traceback (most recent call last):
  File "/usr/local/lib/python2.7/site-packages/flask/app.py", line 1982, in wsgi_app
    response = self.full_dispatch_request()
  File "/usr/local/lib/python2.7/site-packages/flask/app.py", line 1614, in full_dispatch_request
    rv = self.handle_user_exception(e)
  File "/usr/local/lib/python2.7/site-packages/flask/app.py", line 1517, in handle_user_exception
    reraise(exc_type, exc_value, tb)
  File "/usr/local/lib/python2.7/site-packages/flask/app.py", line 1612, in full_dispatch_request
    rv = self.dispatch_request()
  File "/usr/local/lib/python2.7/site-packages/flask/app.py", line 1598, in dispatch_request
    return self.view_functions[rule.endpoint](**req.view_args)
  File "/usr/local/lib/python2.7/site-packages/flask_login/utils.py", line 228, in decorated_view
    return func(*args, **kwargs)
  File "/Users/zouyang/PycharmProjects/GMTools_Flask/route.py", line 409, in gm_tools_controls_profile
    profile['name'], profile['static_info'], profile['dynamic_info'] = query_player_from_dbs(uuid)
  File "/Users/zouyang/PycharmProjects/GMTools_Flask/route.py", line 973, in query_player_from_dbs
    return name, static_info, dynamic_info
UnboundLocalError: local variable 'name' referenced before assignment
Exception on /gm/gmtools/profile/11951050037377 [GET]
Traceback (most recent call last):
  File "/usr/local/lib/python2.7/site-packages/flask/app.py", line 1982, in wsgi_app
    response = self.full_dispatch_request()
  File "/usr/local/lib/python2.7/site-packages/flask/app.py", line 1614, in full_dispatch_request
    rv = self.handle_user_exception(e)
  File "/usr/local/lib/python2.7/site-packages/flask/app.py", line 1517, in handle_user_exception
    reraise(exc_type, exc_value, tb)
  File "/usr/local/lib/python2.7/site-packages/flask/app.py", line 1612, in full_dispatch_request
    rv = self.dispatch_request()
  File "/usr/local/lib/python2.7/site-packages/flask/app.py", line 1598, in dispatch_request
    return self.view_functions[rule.endpoint](**req.view_args)
  File "/usr/local/lib/python2.7/site-packages/flask_login/utils.py", line 228, in decorated_view
    return func(*args, **kwargs)
  File "/Users/zouyang/PycharmProjects/GMTools_Flask/route.py", line 409, in gm_tools_controls_profile
    profile['name'], profile['static_info'], profile['dynamic_info'] = query_player_from_dbs(uuid)
  File "/Users/zouyang/PycharmProjects/GMTools_Flask/route.py", line 967, in query_player_from_dbs
    name = p.nick
AttributeError: 'dict' object has no attribute 'nick'
